Workbook
Name OTSQuery: 'GBG DASHBOARD'!$E$9
Name PlayerAltNames: 'Team Info From Paste'!$F$17:$J$17
Name PlayerMonsDropDown: 'Team Info From Paste'!$C$12:$C$18
Name MoveNames: 'Move Data TABLE'!$D$2:$D$6000
Name ReplayLinksTable: 'Replay Entries'!$B$7:$C$506
Name ReplayLinks: 'Replay Entries'!$C$7:$C$506
Name PokemonIcons: Icons!$B$2:$C$1251
Name Player2: 'Base Data'!$I$3:$I$502
Name BaseDataTable: 'Base Data'!$A$2:$EO$502
Name MatchupDataTableWithHeaders: OpponentData!$C$1:$H$402
Name MoveMons: 'Move Data TABLE'!$C$2:$C$6000
Name ELOQuery: 'GBG DASHBOARD'!$E$11
Name OppMonsUsed: 'Base Bo3 Data'!$DJ$3:$DM$501
Name Paste: Home!$G$8
Name LeadComboTable: 'Lead Combo Reporting'!$F$5:$J$20
Name GameResults: 'Base Bo3 Data'!$EG$3:$EG$502
Name RestrictedLegendaries: OpponentData!$J$19:$J$48
Name Player2PokemonBo3: 'Base Bo3 Data'!$K$3:$P$502
Name TeamName: 'Team Info From Paste'!$E$19
Name GameResultsTable: 'Base Data'!$EF$3:$EF$502
Name Paste: Home!$G$8
Name OppBackQuery: 'GBG DASHBOARD'!$E$4
Name OppLeadQuery: 'GBG DASHBOARD'!$E$3
Name Player1Name: 'Base Data'!$B$3:$B$502
Name PlayerUsedQuery: 'GBG DASHBOARD'!$E$5
Name Bo3data: 'Base Bo3 Data'!$A$2:$AG$502
Name OppMonsUsed: 'Base Data'!$DI$3:$DL$502
Name TypeIcons: Icons!$D$2:$E$20
Name SPD_RANGE: 'Training Steps'!$F$11
Name PlayerBackQuery: 'GBG DASHBOARD'!$E$7
Name MatchupDataTableNoHeaders: OpponentData!$C$2:$H$402
Name FilteredPlayerLeadTable: 'Filtered Lead Combo Reporting'!$A$5:$D$505
Name Player2Name: 'Base Bo3 Data'!$J$3:$J$502
Name GameResultsTableFiltered: 'GBG Filtered'!$B$2:$B$1000
Name WinPercentOTS: Report!$B$11
Name MoveCounts: 'Move Data TABLE'!$F$2:$F$6000
Name OppTeamQuery: 'GBG DASHBOARD'!$E$2
Name ActiveFilterDescriptions: 'GBG DASHBOARD'!$F$1:$F$11
Name OTSDropDown: 'GBG DASHBOARD'!$A$16:$A$18
Name SPE_RANGE: 'Training Steps'!$F$12
Name LeadComboTable: 'Filtered Lead Combo Reporting'!$F$5:$J$20
Name PlayerLeadQuery: 'GBG DASHBOARD'!$E$6
Name Player1: 'Base Bo3 Data'!$B$3:$B$502
Name ResultsDropdown: 'GBG DASHBOARD'!$A$12:$A$14
Name OppMonsOwned: 'Base Data'!$DZ$3:$EE$502
Name ResultQuery: 'GBG DASHBOARD'!$E$1
Name DEF_RANGE: 'Training Steps'!$F$9
Name BaseBo3Results: 'Base Bo3 Data'!$Q$3:$Q$501
Name HP_RANGE: 'Training Steps'!$F$7
Name Player1Pokemon: 'Base Data'!$C$3:$H$502
Name Results: 'Base Data'!$P$3:$P$502
Name WinPercentCTS: Report!$B$12
Name FormFixes: Forms!$A$2:$C$161
Name Player1PokemonSix: 'Base Bo3 Data'!$C$3:$I$502
Name WinPercent: Report!$B$10
Name Player2Pokemon: 'Base Data'!$J$3:$O$502
Name ATK_RANGE: 'Training Steps'!$F$8
Name SPA_RANGE: 'Training Steps'!$F$10
Name PlayerTeraQuery: 'GBG DASHBOARD'!$E$8
Name PlayerLeadTable: 'Lead Combo Reporting'!$A$5:$D$505

Sheet FAQ  Contact
C2: PALKIA Academy Showdown Reporting Spreadsheet
C3: A Project By Bauerdad and v0Lt
C5: =IMAGE("https://cdn-icons-png.flaticon.com/512/3670/3670157.png") -> #REF! | D5: Bauerdad | F5: Feel free to reach out to me via Discord if you have any questions or comments about this project!
C7: =IMAGE("https://cdn-icons-png.flaticon.com/512/3670/3670157.png") -> #REF! | D7: PALKIA Academy | F7: Support me on Ko-Fi
C8: =IMAGE("https://uploads-ssl.webflow.com/5c14e387dab576fe667689cf/64f1a9ddd0246590df69e9ef_ko-fi_logo_02-p-500.png") -> #REF! | D8: PASRS | H8: Ver 7.0, (APR 12, '26)
C11: Tips and Tricks
C12: * Be sure to use a consistent team and a paste to match (even nicknames) for every game! * When you're ready to make changes to your team, Make a new copy of this spreadsheet and start using the new paste there!
C17: Current Limitations
C18: * Pokepastes with fewer than 6 Pokémon are not supported * PASRS is only tested for VGC Doubles on Pokémon Showdown. Other formats are not supported. * Urshifu won't work on "Pokémon Used" filter, but DOES on the lead/back filter * Ditto is PARTIALLY supported (move charts will not work) * Zoroark replays can break if the illusion is removed by something other than an attack (e.g. Weezing)

Sheet Home
D2: PALKIA Academy Showdown Reporting Spreadsheet - V7.0 (Champions Ready) | K2: =Image("https://www.pokemon.com/static-assets/content-assets/cms2/img/video-games/video-games/pokemon_champions/pokemon-champions-logo-169.png") -> #REF!
C4: Step 1 - File -> Make a copy (you cannot edit this file directly)
C6: Step 2 - Put your Showdown Name(s) Here → | G6: Bauerdad
C8: Step 3 - Put your Team Pokepaste Here → | G8: https://pokepast.es/93b3bf538407c484
D10: =Errors!E2 | H10: =TeamName -> WyatVGC's Floette Charizard-Y Team QBXKWXL05U
C11: =Errors!F2 | H11: =VLOOKUP('Team Info From Paste'!D2, PokemonIcons, 2, False) -> #REF! | I11: =VLOOKUP('Team Info From Paste'!D3, PokemonIcons, 2, False) -> #REF! | J11: =VLOOKUP('Team Info From Paste'!D4, PokemonIcons, 2, False) -> #REF!
H12: =VLOOKUP('Team Info From Paste'!D5, PokemonIcons, 2, False) -> #REF! | I12: =VLOOKUP('Team Info From Paste'!D6, PokemonIcons, 2, False) -> #REF! | J12: =VLOOKUP('Team Info From Paste'!D7, PokemonIcons, 2, False) -> #REF!
C14: Step 4 - Add your replay links to the | F14: Replay Entries | H14: Tab and PASRS does the rest!

Sheet Replay Entries
D2: PALKIA Academy Showdown Reporting Spreadsheet - V7.0
C3: =Errors!E2 & IF((Errors!E2 <> ""), " - ", "") & Errors!F2
C4: Jump To: | D4: Games Stats | E4: Match Stats | G4: Matchup Data | J4: Move Usage | N4: FAQ/Contact Page
C6: Game Links Below | H6: Opposing Team | N6: Notes
B7: 1 | F7: =IF(COUNTIF(ReplayLinks,C7) > 1, "DUPE", "") | G7: =IF('GBG Data'!C2 <> "", IF('GBG Data'!C2 = "Loss", "L", IF('GBG Data'!C2 = "Win", "W")), "") | H7: =IF('Base Data'!DZ3 <> "", VLOOKUP(IFERROR(VLOOKUP('Base Data'!DZ3, FormFixes, 2, false), 'Base Data'!DZ3), PokemonIcons, 2, False), "") | I7: =IF('Base Data'!EA3 <> "", VLOOKUP(IFERROR(VLOOKUP('Base Data'!EA3, FormFixes, 2, false), 'Base Data'!EA3), PokemonIcons, 2, False), "") | J7: =IF('Base Data'!EB3 <> "", VLOOKUP(IFERROR(VLOOKUP('Base Data'!EB3, FormFixes, 2, false), 'Base Data'!EB3), PokemonIcons, 2, False), "") | K7: =IF('Base Data'!EC3 <> "", VLOOKUP(IFERROR(VLOOKUP('Base Data'!EC3, FormFixes, 2, false), 'Base Data'!EC3), PokemonIcons, 2, False), "") | L7: =IF('Base Data'!ED3 <> "", VLOOKUP(IFERROR(VLOOKUP('Base Data'!ED3, FormFixes, 2, false), 'Base Data'!ED3), PokemonIcons, 2, False), "") | M7: =IF('Base Data'!EE3 <> "", VLOOKUP(IFERROR(VLOOKUP('Base Data'!EE3, FormFixes, 2, false), 'Base Data'!EE3), PokemonIcons, 2, False), "")
B8: 2 | F8: =IF(COUNTIF(ReplayLinks,C8) > 1, "DUPE", "") | G8: =IF('GBG Data'!C3 <> "", IF('GBG Data'!C3 = "Loss", "L", IF('GBG Data'!C3 = "Win", "W")), "") | H8: =IF('Base Data'!DZ4 <> "", VLOOKUP(IFERROR(VLOOKUP('Base Data'!DZ4, FormFixes, 2, false), 'Base Data'!DZ4), PokemonIcons, 2, False), "") | I8: =IF('Base Data'!EA4 <> "", VLOOKUP(IFERROR(VLOOKUP('Base Data'!EA4, FormFixes, 2, false), 'Base Data'!EA4), PokemonIcons, 2, False), "") | J8: =IF('Base Data'!EB4 <> "", VLOOKUP(IFERROR(VLOOKUP('Base Data'!EB4, FormFixes, 2, false), 'Base Data'!EB4), PokemonIcons, 2, False), "") | K8: =IF('Base Data'!EC4 <> "", VLOOKUP(IFERROR(VLOOKUP('Base Data'!EC4, FormFixes, 2, false), 'Base Data'!EC4), PokemonIcons, 2, False), "") | L8: =IF('Base Data'!ED4 <> "", VLOOKUP(IFERROR(VLOOKUP('Base Data'!ED4, FormFixes, 2, false), 'Base Data'!ED4), PokemonIcons, 2, False), "") | M8: =IF('Base Data'!EE4 <> "", VLOOKUP(IFERROR(VLOOKUP('Base Data'!EE4, FormFixes, 2, false), 'Base Data'!EE4), PokemonIcons, 2, False), "")
B9: 3 | F9: =IF(COUNTIF(ReplayLinks,C9) > 1, "DUPE", "") | G9: =IF('GBG Data'!C4 <> "", IF('GBG Data'!C4 = "Loss", "L", IF('GBG Data'!C4 = "Win", "W")), "") | H9: =IF('Base Data'!DZ5 <> "", VLOOKUP(IFERROR(VLOOKUP('Base Data'!DZ5, FormFixes, 2, false), 'Base Data'!DZ5), PokemonIcons, 2, False), "") | I9: =IF('Base Data'!EA5 <> "", VLOOKUP(IFERROR(VLOOKUP('Base Data'!EA5, FormFixes, 2, false), 'Base Data'!EA5), PokemonIcons, 2, False), "") | J9: =IF('Base Data'!EB5 <> "", VLOOKUP(IFERROR(VLOOKUP('Base Data'!EB5, FormFixes, 2, false), 'Base Data'!EB5), PokemonIcons, 2, False), "") | K9: =IF('Base Data'!EC5 <> "", VLOOKUP(IFERROR(VLOOKUP('Base Data'!EC5, FormFixes, 2, false), 'Base Data'!EC5), PokemonIcons, 2, False), "") | L9: =IF('Base Data'!ED5 <> "", VLOOKUP(IFERROR(VLOOKUP('Base Data'!ED5, FormFixes, 2, false), 'Base Data'!ED5), PokemonIcons, 2, False), "") | M9: =IF('Base Data'!EE5 <> "", VLOOKUP(IFERROR(VLOOKUP('Base Data'!EE5, FormFixes, 2, false), 'Base Data'!EE5), PokemonIcons, 2, False), "")
B10: 4 | F10: =IF(COUNTIF(ReplayLinks,C10) > 1, "DUPE", "") | G10: =IF('GBG Data'!C5 <> "", IF('GBG Data'!C5 = "Loss", "L", IF('GBG Data'!C5 = "Win", "W")), "") | H10: =IF('Base Data'!DZ6 <> "", VLOOKUP(IFERROR(VLOOKUP('Base Data'!DZ6, FormFixes, 2, false), 'Base Data'!DZ6), PokemonIcons, 2, False), "") | I10: =IF('Base Data'!EA6 <> "", VLOOKUP(IFERROR(VLOOKUP('Base Data'!EA6, FormFixes, 2, false), 'Base Data'!EA6), PokemonIcons, 2, False), "") | J10: =IF('Base Data'!EB6 <> "", VLOOKUP(IFERROR(VLOOKUP('Base Data'!EB6, FormFixes, 2, false), 'Base Data'!EB6), PokemonIcons, 2, False), "") | K10: =IF('Base Data'!EC6 <> "", VLOOKUP(IFERROR(VLOOKUP('Base Data'!EC6, FormFixes, 2, false), 'Base Data'!EC6), PokemonIcons, 2, False), "") | L10: =IF('Base Data'!ED6 <> "", VLOOKUP(IFERROR(VLOOKUP('Base Data'!ED6, FormFixes, 2, false), 'Base Data'!ED6), PokemonIcons, 2, False), "") | M10: =IF('Base Data'!EE6 <> "", VLOOKUP(IFERROR(VLOOKUP('Base Data'!EE6, FormFixes, 2, false), 'Base Data'!EE6), PokemonIcons, 2, False), "")
B11: 5 | F11: =IF(COUNTIF(ReplayLinks,C11) > 1, "DUPE", "") | G11: =IF('GBG Data'!C6 <> "", IF('GBG Data'!C6 = "Loss", "L", IF('GBG Data'!C6 = "Win", "W")), "") | H11: =IF('Base Data'!DZ7 <> "", VLOOKUP(IFERROR(VLOOKUP('Base Data'!DZ7, FormFixes, 2, false), 'Base Data'!DZ7), PokemonIcons, 2, False), "") | I11: =IF('Base Data'!EA7 <> "", VLOOKUP(IFERROR(VLOOKUP('Base Data'!EA7, FormFixes, 2, false), 'Base Data'!EA7), PokemonIcons, 2, False), "") | J11: =IF('Base Data'!EB7 <> "", VLOOKUP(IFERROR(VLOOKUP('Base Data'!EB7, FormFixes, 2, false), 'Base Data'!EB7), PokemonIcons, 2, False), "") | K11: =IF('Base Data'!EC7 <> "", VLOOKUP(IFERROR(VLOOKUP('Base Data'!EC7, FormFixes, 2, false), 'Base Data'!EC7), PokemonIcons, 2, False), "") | L11: =IF('Base Data'!ED7 <> "", VLOOKUP(IFERROR(VLOOKUP('Base Data'!ED7, FormFixes, 2, false), 'Base Data'!ED7), PokemonIcons, 2, False), "") | M11: =IF('Base Data'!EE7 <> "", VLOOKUP(IFERROR(VLOOKUP('Base Data'!EE7, FormFixes, 2, false), 'Base Data'!EE7), PokemonIcons, 2, False), "")
B12: 6 | F12: =IF(COUNTIF(ReplayLinks,C12) > 1, "DUPE", "") | G12: =IF('GBG Data'!C7 <> "", IF('GBG Data'!C7 = "Loss", "L", IF('GBG Data'!C7 = "Win", "W")), "") | H12: =IF('Base Data'!DZ8 <> "", VLOOKUP(IFERROR(VLOOKUP('Base Data'!DZ8, FormFixes, 2, false), 'Base Data'!DZ8), PokemonIcons, 2, False), "") | I12: =IF('Base Data'!EA8 <> "", VLOOKUP(IFERROR(VLOOKUP('Base Data'!EA8, FormFixes, 2, false), 'Base Data'!EA8), PokemonIcons, 2, False), "") | J12: =IF('Base Data'!EB8 <> "", VLOOKUP(IFERROR(VLOOKUP('Base Data'!EB8, FormFixes, 2, false), 'Base Data'!EB8), PokemonIcons, 2, False), "") | K12: =IF('Base Data'!EC8 <> "", VLOOKUP(IFERROR(VLOOKUP('Base Data'!EC8, FormFixes, 2, false), 'Base Data'!EC8), PokemonIcons, 2, False), "") | L12: =IF('Base Data'!ED8 <> "", VLOOKUP(IFERROR(VLOOKUP('Base Data'!ED8, FormFixes, 2, false), 'Base Data'!ED8), PokemonIcons, 2, False), "") | M12: =IF('Base Data'!EE8 <> "", VLOOKUP(IFERROR(VLOOKUP('Base Data'!EE8, FormFixes, 2, false), 'Base Data'!EE8), PokemonIcons, 2, False), "")
B13: 7 | F13: =IF(COUNTIF(ReplayLinks,C13) > 1, "DUPE", "") | G13: =IF('GBG Data'!C8 <> "", IF('GBG Data'!C8 = "Loss", "L", IF('GBG Data'!C8 = "Win", "W")), "") | H13: =IF('Base Data'!DZ9 <> "", VLOOKUP(IFERROR(VLOOKUP('Base Data'!DZ9, FormFixes, 2, false), 'Base Data'!DZ9), PokemonIcons, 2, False), "") | I13: =IF('Base Data'!EA9 <> "", VLOOKUP(IFERROR(VLOOKUP('Base Data'!EA9, FormFixes, 2, false), 'Base Data'!EA9), PokemonIcons, 2, False), "") | J13: =IF('Base Data'!EB9 <> "", VLOOKUP(IFERROR(VLOOKUP('Base Data'!EB9, FormFixes, 2, false), 'Base Data'!EB9), PokemonIcons, 2, False), "") | K13: =IF('Base Data'!EC9 <> "", VLOOKUP(IFERROR(VLOOKUP('Base Data'!EC9, FormFixes, 2, false), 'Base Data'!EC9), PokemonIcons, 2, False), "") | L13: =IF('Base Data'!ED9 <> "", VLOOKUP(IFERROR(VLOOKUP('Base Data'!ED9, FormFixes, 2, false), 'Base Data'!ED9), PokemonIcons, 2, False), "") | M13: =IF('Base Data'!EE9 <> "", VLOOKUP(IFERROR(VLOOKUP('Base Data'!EE9, FormFixes, 2, false), 'Base Data'!EE9), PokemonIcons, 2, False), "")
B14: 8 | F14: =IF(COUNTIF(ReplayLinks,C14) > 1, "DUPE", "") | G14: =IF('GBG Data'!C9 <> "", IF('GBG Data'!C9 = "Loss", "L", IF('GBG Data'!C9 = "Win", "W")), "") | H14: =IF('Base Data'!DZ10 <> "", VLOOKUP(IFERROR(VLOOKUP('Base Data'!DZ10, FormFixes, 2, false), 'Base Data'!DZ10), PokemonIcons, 2, False), "") | I14: =IF('Base Data'!EA10 <> "", VLOOKUP(IFERROR(VLOOKUP('Base Data'!EA10, FormFixes, 2, false), 'Base Data'!EA10), PokemonIcons, 2, False), "") | J14: =IF('Base Data'!EB10 <> "", VLOOKUP(IFERROR(VLOOKUP('Base Data'!EB10, FormFixes, 2, false), 'Base Data'!EB10), PokemonIcons, 2, False), "") | K14: =IF('Base Data'!EC10 <> "", VLOOKUP(IFERROR(VLOOKUP('Base Data'!EC10, FormFixes, 2, false), 'Base Data'!EC10), PokemonIcons, 2, False), "") | L14: =IF('Base Data'!ED10 <> "", VLOOKUP(IFERROR(VLOOKUP('Base Data'!ED10, FormFixes, 2, false), 'Base Data'!ED10), PokemonIcons, 2, False), "") | M14: =IF('Base Data'!EE10 <> "", VLOOKUP(IFERROR(VLOOKUP('Base Data'!EE10, FormFixes, 2, false), 'Base Data'!EE10), PokemonIcons, 2, False), "")
B15: 9 | F15: =IF(COUNTIF(ReplayLinks,C15) > 1, "DUPE", "") | G15: =IF('GBG Data'!C10 <> "", IF('GBG Data'!C10 = "Loss", "L", IF('GBG Data'!C10 = "Win", "W")), "") | H15: =IF('Base Data'!DZ11 <> "", VLOOKUP(IFERROR(VLOOKUP('Base Data'!DZ11, FormFixes, 2, false), 'Base Data'!DZ11), PokemonIcons, 2, False), "") | I15: =IF('Base Data'!EA11 <> "", VLOOKUP(IFERROR(VLOOKUP('Base Data'!EA11, FormFixes, 2, false), 'Base Data'!EA11), PokemonIcons, 2, False), "") | J15: =IF('Base Data'!EB11 <> "", VLOOKUP(IFERROR(VLOOKUP('Base Data'!EB11, FormFixes, 2, false), 'Base Data'!EB11), PokemonIcons, 2, False), "") | K15: =IF('Base Data'!EC11 <> "", VLOOKUP(IFERROR(VLOOKUP('Base Data'!EC11, FormFixes, 2, false), 'Base Data'!EC11), PokemonIcons, 2, False), "") | L15: =IF('Base Data'!ED11 <> "", VLOOKUP(IFERROR(VLOOKUP('Base Data'!ED11, FormFixes, 2, false), 'Base Data'!ED11), PokemonIcons, 2, False), "") | M15: =IF('Base Data'!EE11 <> "", VLOOKUP(IFERROR(VLOOKUP('Base Data'!EE11, FormFixes, 2, false), 'Base Data'!EE11), PokemonIcons, 2, False), "")
B16: 10 | F16: =IF(COUNTIF(ReplayLinks,C16) > 1, "DUPE", "") | G16: =IF('GBG Data'!C11 <> "", IF('GBG Data'!C11 = "Loss", "L", IF('GBG Data'!C11 = "Win", "W")), "") | H16: =IF('Base Data'!DZ12 <> "", VLOOKUP(IFERROR(VLOOKUP('Base Data'!DZ12, FormFixes, 2, false), 'Base Data'!DZ12), PokemonIcons, 2, False), "") | I16: =IF('Base Data'!EA12 <> "", VLOOKUP(IFERROR(VLOOKUP('Base Data'!EA12, FormFixes, 2, false), 'Base Data'!EA12), PokemonIcons, 2, False), "") | J16: =IF('Base Data'!EB12 <> "", VLOOKUP(IFERROR(VLOOKUP('Base Data'!EB12, FormFixes, 2, false), 'Base Data'!EB12), PokemonIcons, 2, False), "") | K16: =IF('Base Data'!EC12 <> "", VLOOKUP(IFERROR(VLOOKUP('Base Data'!EC12, FormFixes, 2, false), 'Base Data'!EC12), PokemonIcons, 2, False), "") | L16: =IF('Base Data'!ED12 <> "", VLOOKUP(IFERROR(VLOOKUP('Base Data'!ED12, FormFixes, 2, false), 'Base Data'!ED12), PokemonIcons, 2, False), "") | M16: =IF('Base Data'!EE12 <> "", VLOOKUP(IFERROR(VLOOKUP('Base Data'!EE12, FormFixes, 2, false), 'Base Data'!EE12), PokemonIcons, 2, False), "")
B17: 11 | F17: =IF(COUNTIF(ReplayLinks,C17) > 1, "DUPE", "") | G17: =IF('GBG Data'!C12 <> "", IF('GBG Data'!C12 = "Loss", "L", IF('GBG Data'!C12 = "Win", "W")), "") | H17: =IF('Base Data'!DZ13 <> "", VLOOKUP(IFERROR(VLOOKUP('Base Data'!DZ13, FormFixes, 2, false), 'Base Data'!DZ13), PokemonIcons, 2, False), "") | I17: =IF('Base Data'!EA13 <> "", VLOOKUP(IFERROR(VLOOKUP('Base Data'!EA13, FormFixes, 2, false), 'Base Data'!EA13), PokemonIcons, 2, False), "") | J17: =IF('Base Data'!EB13 <> "", VLOOKUP(IFERROR(VLOOKUP('Base Data'!EB13, FormFixes, 2, false), 'Base Data'!EB13), PokemonIcons, 2, False), "") | K17: =IF('Base Data'!EC13 <> "", VLOOKUP(IFERROR(VLOOKUP('Base Data'!EC13, FormFixes, 2, false), 'Base Data'!EC13), PokemonIcons, 2, False), "") | L17: =IF('Base Data'!ED13 <> "", VLOOKUP(IFERROR(VLOOKUP('Base Data'!ED13, FormFixes, 2, false), 'Base Data'!ED13), PokemonIcons, 2, False), "") | M17: =IF('Base Data'!EE13 <> "", VLOOKUP(IFERROR(VLOOKUP('Base Data'!EE13, FormFixes, 2, false), 'Base Data'!EE13), PokemonIcons, 2, False), "")
B18: 12 | F18: =IF(COUNTIF(ReplayLinks,C18) > 1, "DUPE", "") | G18: =IF('GBG Data'!C13 <> "", IF('GBG Data'!C13 = "Loss", "L", IF('GBG Data'!C13 = "Win", "W")), "") | H18: =IF('Base Data'!DZ14 <> "", VLOOKUP(IFERROR(VLOOKUP('Base Data'!DZ14, FormFixes, 2, false), 'Base Data'!DZ14), PokemonIcons, 2, False), "") | I18: =IF('Base Data'!EA14 <> "", VLOOKUP(IFERROR(VLOOKUP('Base Data'!EA14, FormFixes, 2, false), 'Base Data'!EA14), PokemonIcons, 2, False), "") | J18: =IF('Base Data'!EB14 <> "", VLOOKUP(IFERROR(VLOOKUP('Base Data'!EB14, FormFixes, 2, false), 'Base Data'!EB14), PokemonIcons, 2, False), "") | K18: =IF('Base Data'!EC14 <> "", VLOOKUP(IFERROR(VLOOKUP('Base Data'!EC14, FormFixes, 2, false), 'Base Data'!EC14), PokemonIcons, 2, False), "") | L18: =IF('Base Data'!ED14 <> "", VLOOKUP(IFERROR(VLOOKUP('Base Data'!ED14, FormFixes, 2, false), 'Base Data'!ED14), PokemonIcons, 2, False), "") | M18: =IF('Base Data'!EE14 <> "", VLOOKUP(IFERROR(VLOOKUP('Base Data'!EE14, FormFixes, 2, false), 'Base Data'!EE14), PokemonIcons, 2, False), "")
... B506: 500 | F506: =IF(COUNTIF(ReplayLinks,C506) > 1, "DUPE", "") | G506: =IF('GBG Data'!C501 <> "", IF('GBG Data'!C501 = "Loss", "L", IF('GBG Data'!C501 = "Win", "W")), "") | H506: =IF('Base Data'!DZ502 <> "", VLOOKUP(IFERROR(VLOOKUP('Base Data'!DZ502, FormFixes, 2, false), 'Base Data'!DZ502), PokemonIcons, 2, False), "") | I506: =IF('Base Data'!EA502 <> "", VLOOKUP(IFERROR(VLOOKUP('Base Data'!EA502, FormFixes, 2, false), 'Base Data'!EA502), PokemonIcons, 2, False), "") | J506: =IF('Base Data'!EB502 <> "", VLOOKUP(IFERROR(VLOOKUP('Base Data'!EB502, FormFixes, 2, false), 'Base Data'!EB502), PokemonIcons, 2, False), "") | K506: =IF('Base Data'!EC502 <> "", VLOOKUP(IFERROR(VLOOKUP('Base Data'!EC502, FormFixes, 2, false), 'Base Data'!EC502), PokemonIcons, 2, False), "") | L506: =IF('Base Data'!ED502 <> "", VLOOKUP(IFERROR(VLOOKUP('Base Data'!ED502, FormFixes, 2, false), 'Base Data'!ED502), PokemonIcons, 2, False), "") | M506: =IF('Base Data'!EE502 <> "", VLOOKUP(IFERROR(VLOOKUP('Base Data'!EE502, FormFixes, 2, false), 'Base Data'!EE502), PokemonIcons, 2, False), "")

Sheet Game By Game
B1: ← Hit the + to filter your games! | AE1: Press the [ - ] to collapse
P2: Player | U2: Opponent
P3: Lead | Q3: -any- | U3: Lead | V3: -any-
C4: Result | E4: -any- | G4: Opposing Pokémon | J4: -any- | P4: Back | Q4: -any- | U4: Back | V4: -any- | AA4: -any- | AE4: -any- | AF4: Min Elo: | AG4: -any-
AA5: Mega | AE5: OTS? | AF5: ELO
B7: Game | C7: Result | F7: Replay Links | G7: Opposing Team | P7: Your Picks | U7: Their Picks | AA7: You | AC7: Opp | AF7: You | AG7: Opp
B8: ='GBG Filtered'!A2 | C8: ='GBG Filtered'!B2 | D8: ='GBG Filtered'!C2 | E8: ='GBG Filtered'!D2 | F8: =IF(B8 <> "", HYPERLINK(VLOOKUP( VALUE(B8), ReplayLinksTable, 2, false), "Replay"), "") | G8: =IF('GBG Filtered'!E2 <> "", VLOOKUP(IFERROR(VLOOKUP('GBG Filtered'!E2, FormFixes, 2, false), 'GBG Filtered'!E2), PokemonIcons, 2, False), "") | H8: =IF('GBG Filtered'!F2 <> "", VLOOKUP(IFERROR(VLOOKUP('GBG Filtered'!F2, FormFixes, 2, false), 'GBG Filtered'!F2), PokemonIcons, 2, False), "") | I8: =IF('GBG Filtered'!G2 <> "", VLOOKUP(IFERROR(VLOOKUP('GBG Filtered'!G2, FormFixes, 2, false), 'GBG Filtered'!G2), PokemonIcons, 2, False), "") | J8: =IF('GBG Filtered'!H2 <> "", VLOOKUP(IFERROR(VLOOKUP('GBG Filtered'!H2, FormFixes, 2, false), 'GBG Filtered'!H2), PokemonIcons, 2, False), "") | K8: =IF('GBG Filtered'!I2 <> "", VLOOKUP(IFERROR(VLOOKUP('GBG Filtered'!I2, FormFixes, 2, false), 'GBG Filtered'!I2), PokemonIcons, 2, False), "") | L8: =IF('GBG Filtered'!J2 <> "", VLOOKUP(IFERROR(VLOOKUP('GBG Filtered'!J2, FormFixes, 2, false), 'GBG Filtered'!J2), PokemonIcons, 2, False), "") | P8: =IF('GBG Filtered'!N2 <> "", VLOOKUP(IFERROR(VLOOKUP('GBG Filtered'!N2, FormFixes, 2, false), 'GBG Filtered'!N2), PokemonIcons, 2, False), "") | Q8: =IF('GBG Filtered'!O2 <> "", VLOOKUP(IFERROR(VLOOKUP('GBG Filtered'!O2, FormFixes, 2, false), 'GBG Filtered'!O2), PokemonIcons, 2, False), "") | R8: =IF('GBG Filtered'!P2 <> "", VLOOKUP(IFERROR(VLOOKUP('GBG Filtered'!P2, FormFixes, 2, false), 'GBG Filtered'!P2), PokemonIcons, 2, False), "") | S8: =IF('GBG Filtered'!Q2 <> "", VLOOKUP(IFERROR(VLOOKUP('GBG Filtered'!Q2, FormFixes, 2, false), 'GBG Filtered'!Q2), PokemonIcons, 2, False), "") | U8: =IF('GBG Filtered'!S2 <> "", VLOOKUP(IFERROR(VLOOKUP('GBG Filtered'!S2, FormFixes, 2, false), 'GBG Filtered'!S2), PokemonIcons, 2, False), "") | V8: =IF('GBG Filtered'!T2 <> "", VLOOKUP(IFERROR(VLOOKUP('GBG Filtered'!T2, FormFixes, 2, false), 'GBG Filtered'!T2), PokemonIcons, 2, False), "") | W8: =IF('GBG Filtered'!U2 <> "", VLOOKUP(IFERROR(VLOOKUP('GBG Filtered'!U2, FormFixes, 2, false), 'GBG Filtered'!U2), PokemonIcons, 2, False), "") | X8: =IF('GBG Filtered'!V2 <> "", VLOOKUP(IFERROR(VLOOKUP('GBG Filtered'!V2, FormFixes, 2, false), 'GBG Filtered'!V2), PokemonIcons, 2, False), "") | AA8: =IF('GBG Filtered'!Y2 <> "", VLOOKUP(IFERROR(VLOOKUP('GBG Filtered'!Y2, FormFixes, 2, false), 'GBG Filtered'!Y2), PokemonIcons, 2, False), "") | AB8: =IF('GBG Filtered'!Z2 <> "", VLOOKUP('GBG Filtered'!Z2, TypeIcons, 2, False), "") | AC8: =IF('GBG Filtered'!AA2 <> "", VLOOKUP(IFERROR(VLOOKUP('GBG Filtered'!AA2, FormFixes, 2, false), 'GBG Filtered'!AA2), PokemonIcons, 2, False), "") | AD8: =IF('GBG Filtered'!AB2 <> "", VLOOKUP('GBG Filtered'!AB2, TypeIcons, 2, False), "") | AE8: ='GBG Filtered'!AC2 | AF8: ='GBG Filtered'!AD2 | AG8: ='GBG Filtered'!AE2
B9: ='GBG Filtered'!A3 | C9: ='GBG Filtered'!B3 | D9: ='GBG Filtered'!C3 | E9: ='GBG Filtered'!D3 | F9: =IF(B9 <> "", HYPERLINK(VLOOKUP( VALUE(B9), ReplayLinksTable, 2, false), "Replay"), "") | G9: =IF('GBG Filtered'!E3 <> "", VLOOKUP(IFERROR(VLOOKUP('GBG Filtered'!E3, FormFixes, 2, false), 'GBG Filtered'!E3), PokemonIcons, 2, False), "") | H9: =IF('GBG Filtered'!F3 <> "", VLOOKUP(IFERROR(VLOOKUP('GBG Filtered'!F3, FormFixes, 2, false), 'GBG Filtered'!F3), PokemonIcons, 2, False), "") | I9: =IF('GBG Filtered'!G3 <> "", VLOOKUP(IFERROR(VLOOKUP('GBG Filtered'!G3, FormFixes, 2, false), 'GBG Filtered'!G3), PokemonIcons, 2, False), "") | J9: =IF('GBG Filtered'!H3 <> "", VLOOKUP(IFERROR(VLOOKUP('GBG Filtered'!H3, FormFixes, 2, false), 'GBG Filtered'!H3), PokemonIcons, 2, False), "") | K9: =IF('GBG Filtered'!I3 <> "", VLOOKUP(IFERROR(VLOOKUP('GBG Filtered'!I3, FormFixes, 2, false), 'GBG Filtered'!I3), PokemonIcons, 2, False), "") | L9: =IF('GBG Filtered'!J3 <> "", VLOOKUP(IFERROR(VLOOKUP('GBG Filtered'!J3, FormFixes, 2, false), 'GBG Filtered'!J3), PokemonIcons, 2, False), "") | P9: =IF('GBG Filtered'!N3 <> "", VLOOKUP(IFERROR(VLOOKUP('GBG Filtered'!N3, FormFixes, 2, false), 'GBG Filtered'!N3), PokemonIcons, 2, False), "") | Q9: =IF('GBG Filtered'!O3 <> "", VLOOKUP(IFERROR(VLOOKUP('GBG Filtered'!O3, FormFixes, 2, false), 'GBG Filtered'!O3), PokemonIcons, 2, False), "") | R9: =IF('GBG Filtered'!P3 <> "", VLOOKUP(IFERROR(VLOOKUP('GBG Filtered'!P3, FormFixes, 2, false), 'GBG Filtered'!P3), PokemonIcons, 2, False), "") | S9: =IF('GBG Filtered'!Q3 <> "", VLOOKUP(IFERROR(VLOOKUP('GBG Filtered'!Q3, FormFixes, 2, false), 'GBG Filtered'!Q3), PokemonIcons, 2, False), "") | U9: =IF('GBG Filtered'!S3 <> "", VLOOKUP(IFERROR(VLOOKUP('GBG Filtered'!S3, FormFixes, 2, false), 'GBG Filtered'!S3), PokemonIcons, 2, False), "") | V9: =IF('GBG Filtered'!T3 <> "", VLOOKUP(IFERROR(VLOOKUP('GBG Filtered'!T3, FormFixes, 2, false), 'GBG Filtered'!T3), PokemonIcons, 2, False), "") | W9: =IF('GBG Filtered'!U3 <> "", VLOOKUP(IFERROR(VLOOKUP('GBG Filtered'!U3, FormFixes, 2, false), 'GBG Filtered'!U3), PokemonIcons, 2, False), "") | X9: =IF('GBG Filtered'!V3 <> "", VLOOKUP(IFERROR(VLOOKUP('GBG Filtered'!V3, FormFixes, 2, false), 'GBG Filtered'!V3), PokemonIcons, 2, False), "") | AA9: =IF('GBG Filtered'!Y3 <> "", VLOOKUP(IFERROR(VLOOKUP('GBG Filtered'!Y3, FormFixes, 2, false), 'GBG Filtered'!Y3), PokemonIcons, 2, False), "") | AB9: =IF('GBG Filtered'!Z3 <> "", VLOOKUP('GBG Filtered'!Z3, TypeIcons, 2, False), "") | AC9: =IF('GBG Filtered'!AA3 <> "", VLOOKUP(IFERROR(VLOOKUP('GBG Filtered'!AA3, FormFixes, 2, false), 'GBG Filtered'!AA3), PokemonIcons, 2, False), "") | AD9: =IF('GBG Filtered'!AB3 <> "", VLOOKUP('GBG Filtered'!AB3, TypeIcons, 2, False), "") | AE9: ='GBG Filtered'!AC3 | AF9: ='GBG Filtered'!AD3 | AG9: ='GBG Filtered'!AE3
B10: ='GBG Filtered'!A4 | C10: ='GBG Filtered'!B4 | D10: ='GBG Filtered'!C4 | E10: ='GBG Filtered'!D4 | F10: =IF(B10 <> "", HYPERLINK(VLOOKUP( VALUE(B10), ReplayLinksTable, 2, false), "Replay"), "") | G10: =IF('GBG Filtered'!E4 <> "", VLOOKUP(IFERROR(VLOOKUP('GBG Filtered'!E4, FormFixes, 2, false), 'GBG Filtered'!E4), PokemonIcons, 2, False), "") | H10: =IF('GBG Filtered'!F4 <> "", VLOOKUP(IFERROR(VLOOKUP('GBG Filtered'!F4, FormFixes, 2, false), 'GBG Filtered'!F4), PokemonIcons, 2, False), "") | I10: =IF('GBG Filtered'!G4 <> "", VLOOKUP(IFERROR(VLOOKUP('GBG Filtered'!G4, FormFixes, 2, false), 'GBG Filtered'!G4), PokemonIcons, 2, False), "") | J10: =IF('GBG Filtered'!H4 <> "", VLOOKUP(IFERROR(VLOOKUP('GBG Filtered'!H4, FormFixes, 2, false), 'GBG Filtered'!H4), PokemonIcons, 2, False), "") | K10: =IF('GBG Filtered'!I4 <> "", VLOOKUP(IFERROR(VLOOKUP('GBG Filtered'!I4, FormFixes, 2, false), 'GBG Filtered'!I4), PokemonIcons, 2, False), "") | L10: =IF('GBG Filtered'!J4 <> "", VLOOKUP(IFERROR(VLOOKUP('GBG Filtered'!J4, FormFixes, 2, false), 'GBG Filtered'!J4), PokemonIcons, 2, False), "") | P10: =IF('GBG Filtered'!N4 <> "", VLOOKUP(IFERROR(VLOOKUP('GBG Filtered'!N4, FormFixes, 2, false), 'GBG Filtered'!N4), PokemonIcons, 2, False), "") | Q10: =IF('GBG Filtered'!O4 <> "", VLOOKUP(IFERROR(VLOOKUP('GBG Filtered'!O4, FormFixes, 2, false), 'GBG Filtered'!O4), PokemonIcons, 2, False), "") | R10: =IF('GBG Filtered'!P4 <> "", VLOOKUP(IFERROR(VLOOKUP('GBG Filtered'!P4, FormFixes, 2, false), 'GBG Filtered'!P4), PokemonIcons, 2, False), "") | S10: =IF('GBG Filtered'!Q4 <> "", VLOOKUP(IFERROR(VLOOKUP('GBG Filtered'!Q4, FormFixes, 2, false), 'GBG Filtered'!Q4), PokemonIcons, 2, False), "") | U10: =IF('GBG Filtered'!S4 <> "", VLOOKUP(IFERROR(VLOOKUP('GBG Filtered'!S4, FormFixes, 2, false), 'GBG Filtered'!S4), PokemonIcons, 2, False), "") | V10: =IF('GBG Filtered'!T4 <> "", VLOOKUP(IFERROR(VLOOKUP('GBG Filtered'!T4, FormFixes, 2, false), 'GBG Filtered'!T4), PokemonIcons, 2, False), "") | W10: =IF('GBG Filtered'!U4 <> "", VLOOKUP(IFERROR(VLOOKUP('GBG Filtered'!U4, FormFixes, 2, false), 'GBG Filtered'!U4), PokemonIcons, 2, False), "") | X10: =IF('GBG Filtered'!V4 <> "", VLOOKUP(IFERROR(VLOOKUP('GBG Filtered'!V4, FormFixes, 2, false), 'GBG Filtered'!V4), PokemonIcons, 2, False), "") | AA10: =IF('GBG Filtered'!Y4 <> "", VLOOKUP(IFERROR(VLOOKUP('GBG Filtered'!Y4, FormFixes, 2, false), 'GBG Filtered'!Y4), PokemonIcons, 2, False), "") | AB10: =IF('GBG Filtered'!Z4 <> "", VLOOKUP('GBG Filtered'!Z4, TypeIcons, 2, False), "") | AC10: =IF('GBG Filtered'!AA4 <> "", VLOOKUP(IFERROR(VLOOKUP('GBG Filtered'!AA4, FormFixes, 2, false), 'GBG Filtered'!AA4), PokemonIcons, 2, False), "") | AD10: =IF('GBG Filtered'!AB4 <> "", VLOOKUP('GBG Filtered'!AB4, TypeIcons, 2, False), "") | AE10: ='GBG Filtered'!AC4 | AF10: ='GBG Filtered'!AD4 | AG10: ='GBG Filtered'!AE4
B11: ='GBG Filtered'!A5 | C11: ='GBG Filtered'!B5 | D11: ='GBG Filtered'!C5 | E11: ='GBG Filtered'!D5 | F11: =IF(B11 <> "", HYPERLINK(VLOOKUP( VALUE(B11), ReplayLinksTable, 2, false), "Replay"), "") | G11: =IF('GBG Filtered'!E5 <> "", VLOOKUP(IFERROR(VLOOKUP('GBG Filtered'!E5, FormFixes, 2, false), 'GBG Filtered'!E5), PokemonIcons, 2, False), "") | H11: =IF('GBG Filtered'!F5 <> "", VLOOKUP(IFERROR(VLOOKUP('GBG Filtered'!F5, FormFixes, 2, false), 'GBG Filtered'!F5), PokemonIcons, 2, False), "") | I11: =IF('GBG Filtered'!G5 <> "", VLOOKUP(IFERROR(VLOOKUP('GBG Filtered'!G5, FormFixes, 2, false), 'GBG Filtered'!G5), PokemonIcons, 2, False), "") | J11: =IF('GBG Filtered'!H5 <> "", VLOOKUP(IFERROR(VLOOKUP('GBG Filtered'!H5, FormFixes, 2, false), 'GBG Filtered'!H5), PokemonIcons, 2, False), "") | K11: =IF('GBG Filtered'!I5 <> "", VLOOKUP(IFERROR(VLOOKUP('GBG Filtered'!I5, FormFixes, 2, false), 'GBG Filtered'!I5), PokemonIcons, 2, False), "") | L11: =IF('GBG Filtered'!J5 <> "", VLOOKUP(IFERROR(VLOOKUP('GBG Filtered'!J5, FormFixes, 2, false), 'GBG Filtered'!J5), PokemonIcons, 2, False), "") | P11: =IF('GBG Filtered'!N5 <> "", VLOOKUP(IFERROR(VLOOKUP('GBG Filtered'!N5, FormFixes, 2, false), 'GBG Filtered'!N5), PokemonIcons, 2, False), "") | Q11: =IF('GBG Filtered'!O5 <> "", VLOOKUP(IFERROR(VLOOKUP('GBG Filtered'!O5, FormFixes, 2, false), 'GBG Filtered'!O5), PokemonIcons, 2, False), "") | R11: =IF('GBG Filtered'!P5 <> "", VLOOKUP(IFERROR(VLOOKUP('GBG Filtered'!P5, FormFixes, 2, false), 'GBG Filtered'!P5), PokemonIcons, 2, False), "") | S11: =IF('GBG Filtered'!Q5 <> "", VLOOKUP(IFERROR(VLOOKUP('GBG Filtered'!Q5, FormFixes, 2, false), 'GBG Filtered'!Q5), PokemonIcons, 2, False), "") | U11: =IF('GBG Filtered'!S5 <> "", VLOOKUP(IFERROR(VLOOKUP('GBG Filtered'!S5, FormFixes, 2, false), 'GBG Filtered'!S5), PokemonIcons, 2, False), "") | V11: =IF('GBG Filtered'!T5 <> "", VLOOKUP(IFERROR(VLOOKUP('GBG Filtered'!T5, FormFixes, 2, false), 'GBG Filtered'!T5), PokemonIcons, 2, False), "") | W11: =IF('GBG Filtered'!U5 <> "", VLOOKUP(IFERROR(VLOOKUP('GBG Filtered'!U5, FormFixes, 2, false), 'GBG Filtered'!U5), PokemonIcons, 2, False), "") | X11: =IF('GBG Filtered'!V5 <> "", VLOOKUP(IFERROR(VLOOKUP('GBG Filtered'!V5, FormFixes, 2, false), 'GBG Filtered'!V5), PokemonIcons, 2, False), "") | AA11: =IF('GBG Filtered'!Y5 <> "", VLOOKUP(IFERROR(VLOOKUP('GBG Filtered'!Y5, FormFixes, 2, false), 'GBG Filtered'!Y5), PokemonIcons, 2, False), "") | AB11: =IF('GBG Filtered'!Z5 <> "", VLOOKUP('GBG Filtered'!Z5, TypeIcons, 2, False), "") | AC11: =IF('GBG Filtered'!AA5 <> "", VLOOKUP(IFERROR(VLOOKUP('GBG Filtered'!AA5, FormFixes, 2, false), 'GBG Filtered'!AA5), PokemonIcons, 2, False), "") | AD11: =IF('GBG Filtered'!AB5 <> "", VLOOKUP('GBG Filtered'!AB5, TypeIcons, 2, False), "") | AE11: ='GBG Filtered'!AC5 | AF11: ='GBG Filtered'!AD5 | AG11: ='GBG Filtered'!AE5
B12: ='GBG Filtered'!A6 | C12: ='GBG Filtered'!B6 | D12: ='GBG Filtered'!C6 | E12: ='GBG Filtered'!D6 | F12: =IF(B12 <> "", HYPERLINK(VLOOKUP( VALUE(B12), ReplayLinksTable, 2, false), "Replay"), "") | G12: =IF('GBG Filtered'!E6 <> "", VLOOKUP(IFERROR(VLOOKUP('GBG Filtered'!E6, FormFixes, 2, false), 'GBG Filtered'!E6), PokemonIcons, 2, False), "") | H12: =IF('GBG Filtered'!F6 <> "", VLOOKUP(IFERROR(VLOOKUP('GBG Filtered'!F6, FormFixes, 2, false), 'GBG Filtered'!F6), PokemonIcons, 2, False), "") | I12: =IF('GBG Filtered'!G6 <> "", VLOOKUP(IFERROR(VLOOKUP('GBG Filtered'!G6, FormFixes, 2, false), 'GBG Filtered'!G6), PokemonIcons, 2, False), "") | J12: =IF('GBG Filtered'!H6 <> "", VLOOKUP(IFERROR(VLOOKUP('GBG Filtered'!H6, FormFixes, 2, false), 'GBG Filtered'!H6), PokemonIcons, 2, False), "") | K12: =IF('GBG Filtered'!I6 <> "", VLOOKUP(IFERROR(VLOOKUP('GBG Filtered'!I6, FormFixes, 2, false), 'GBG Filtered'!I6), PokemonIcons, 2, False), "") | L12: =IF('GBG Filtered'!J6 <> "", VLOOKUP(IFERROR(VLOOKUP('GBG Filtered'!J6, FormFixes, 2, false), 'GBG Filtered'!J6), PokemonIcons, 2, False), "") | P12: =IF('GBG Filtered'!N6 <> "", VLOOKUP(IFERROR(VLOOKUP('GBG Filtered'!N6, FormFixes, 2, false), 'GBG Filtered'!N6), PokemonIcons, 2, False), "") | Q12: =IF('GBG Filtered'!O6 <> "", VLOOKUP(IFERROR(VLOOKUP('GBG Filtered'!O6, FormFixes, 2, false), 'GBG Filtered'!O6), PokemonIcons, 2, False), "") | R12: =IF('GBG Filtered'!P6 <> "", VLOOKUP(IFERROR(VLOOKUP('GBG Filtered'!P6, FormFixes, 2, false), 'GBG Filtered'!P6), PokemonIcons, 2, False), "") | S12: =IF('GBG Filtered'!Q6 <> "", VLOOKUP(IFERROR(VLOOKUP('GBG Filtered'!Q6, FormFixes, 2, false), 'GBG Filtered'!Q6), PokemonIcons, 2, False), "") | U12: =IF('GBG Filtered'!S6 <> "", VLOOKUP(IFERROR(VLOOKUP('GBG Filtered'!S6, FormFixes, 2, false), 'GBG Filtered'!S6), PokemonIcons, 2, False), "") | V12: =IF('GBG Filtered'!T6 <> "", VLOOKUP(IFERROR(VLOOKUP('GBG Filtered'!T6, FormFixes, 2, false), 'GBG Filtered'!T6), PokemonIcons, 2, False), "") | W12: =IF('GBG Filtered'!U6 <> "", VLOOKUP(IFERROR(VLOOKUP('GBG Filtered'!U6, FormFixes, 2, false), 'GBG Filtered'!U6), PokemonIcons, 2, False), "") | X12: =IF('GBG Filtered'!V6 <> "", VLOOKUP(IFERROR(VLOOKUP('GBG Filtered'!V6, FormFixes, 2, false), 'GBG Filtered'!V6), PokemonIcons, 2, False), "") | AA12: =IF('GBG Filtered'!Y6 <> "", VLOOKUP(IFERROR(VLOOKUP('GBG Filtered'!Y6, FormFixes, 2, false), 'GBG Filtered'!Y6), PokemonIcons, 2, False), "") | AB12: =IF('GBG Filtered'!Z6 <> "", VLOOKUP('GBG Filtered'!Z6, TypeIcons, 2, False), "") | AC12: =IF('GBG Filtered'!AA6 <> "", VLOOKUP(IFERROR(VLOOKUP('GBG Filtered'!AA6, FormFixes, 2, false), 'GBG Filtered'!AA6), PokemonIcons, 2, False), "") | AD12: =IF('GBG Filtered'!AB6 <> "", VLOOKUP('GBG Filtered'!AB6, TypeIcons, 2, False), "") | AE12: ='GBG Filtered'!AC6 | AF12: ='GBG Filtered'!AD6 | AG12: ='GBG Filtered'!AE6
B13: ='GBG Filtered'!A7 | C13: ='GBG Filtered'!B7 | D13: ='GBG Filtered'!C7 | E13: ='GBG Filtered'!D7 | F13: =IF(B13 <> "", HYPERLINK(VLOOKUP( VALUE(B13), ReplayLinksTable, 2, false), "Replay"), "") | G13: =IF('GBG Filtered'!E7 <> "", VLOOKUP(IFERROR(VLOOKUP('GBG Filtered'!E7, FormFixes, 2, false), 'GBG Filtered'!E7), PokemonIcons, 2, False), "") | H13: =IF('GBG Filtered'!F7 <> "", VLOOKUP(IFERROR(VLOOKUP('GBG Filtered'!F7, FormFixes, 2, false), 'GBG Filtered'!F7), PokemonIcons, 2, False), "") | I13: =IF('GBG Filtered'!G7 <> "", VLOOKUP(IFERROR(VLOOKUP('GBG Filtered'!G7, FormFixes, 2, false), 'GBG Filtered'!G7), PokemonIcons, 2, False), "") | J13: =IF('GBG Filtered'!H7 <> "", VLOOKUP(IFERROR(VLOOKUP('GBG Filtered'!H7, FormFixes, 2, false), 'GBG Filtered'!H7), PokemonIcons, 2, False), "") | K13: =IF('GBG Filtered'!I7 <> "", VLOOKUP(IFERROR(VLOOKUP('GBG Filtered'!I7, FormFixes, 2, false), 'GBG Filtered'!I7), PokemonIcons, 2, False), "") | L13: =IF('GBG Filtered'!J7 <> "", VLOOKUP(IFERROR(VLOOKUP('GBG Filtered'!J7, FormFixes, 2, false), 'GBG Filtered'!J7), PokemonIcons, 2, False), "") | P13: =IF('GBG Filtered'!N7 <> "", VLOOKUP(IFERROR(VLOOKUP('GBG Filtered'!N7, FormFixes, 2, false), 'GBG Filtered'!N7), PokemonIcons, 2, False), "") | Q13: =IF('GBG Filtered'!O7 <> "", VLOOKUP(IFERROR(VLOOKUP('GBG Filtered'!O7, FormFixes, 2, false), 'GBG Filtered'!O7), PokemonIcons, 2, False), "") | R13: =IF('GBG Filtered'!P7 <> "", VLOOKUP(IFERROR(VLOOKUP('GBG Filtered'!P7, FormFixes, 2, false), 'GBG Filtered'!P7), PokemonIcons, 2, False), "") | S13: =IF('GBG Filtered'!Q7 <> "", VLOOKUP(IFERROR(VLOOKUP('GBG Filtered'!Q7, FormFixes, 2, false), 'GBG Filtered'!Q7), PokemonIcons, 2, False), "") | U13: =IF('GBG Filtered'!S7 <> "", VLOOKUP(IFERROR(VLOOKUP('GBG Filtered'!S7, FormFixes, 2, false), 'GBG Filtered'!S7), PokemonIcons, 2, False), "") | V13: =IF('GBG Filtered'!T7 <> "", VLOOKUP(IFERROR(VLOOKUP('GBG Filtered'!T7, FormFixes, 2, false), 'GBG Filtered'!T7), PokemonIcons, 2, False), "") | W13: =IF('GBG Filtered'!U7 <> "", VLOOKUP(IFERROR(VLOOKUP('GBG Filtered'!U7, FormFixes, 2, false), 'GBG Filtered'!U7), PokemonIcons, 2, False), "") | X13: =IF('GBG Filtered'!V7 <> "", VLOOKUP(IFERROR(VLOOKUP('GBG Filtered'!V7, FormFixes, 2, false), 'GBG Filtered'!V7), PokemonIcons, 2, False), "") | AA13: =IF('GBG Filtered'!Y7 <> "", VLOOKUP(IFERROR(VLOOKUP('GBG Filtered'!Y7, FormFixes, 2, false), 'GBG Filtered'!Y7), PokemonIcons, 2, False), "") | AB13: =IF('GBG Filtered'!Z7 <> "", VLOOKUP('GBG Filtered'!Z7, TypeIcons, 2, False), "") | AC13: =IF('GBG Filtered'!AA7 <> "", VLOOKUP(IFERROR(VLOOKUP('GBG Filtered'!AA7, FormFixes, 2, false), 'GBG Filtered'!AA7), PokemonIcons, 2, False), "") | AD13: =IF('GBG Filtered'!AB7 <> "", VLOOKUP('GBG Filtered'!AB7, TypeIcons, 2, False), "") | AE13: ='GBG Filtered'!AC7 | AF13: ='GBG Filtered'!AD7 | AG13: ='GBG Filtered'!AE7
B14: ='GBG Filtered'!A8 | C14: ='GBG Filtered'!B8 | D14: ='GBG Filtered'!C8 | E14: ='GBG Filtered'!D8 | F14: =IF(B14 <> "", HYPERLINK(VLOOKUP( VALUE(B14), ReplayLinksTable, 2, false), "Replay"), "") | G14: =IF('GBG Filtered'!E8 <> "", VLOOKUP(IFERROR(VLOOKUP('GBG Filtered'!E8, FormFixes, 2, false), 'GBG Filtered'!E8), PokemonIcons, 2, False), "") | H14: =IF('GBG Filtered'!F8 <> "", VLOOKUP(IFERROR(VLOOKUP('GBG Filtered'!F8, FormFixes, 2, false), 'GBG Filtered'!F8), PokemonIcons, 2, False), "") | I14: =IF('GBG Filtered'!G8 <> "", VLOOKUP(IFERROR(VLOOKUP('GBG Filtered'!G8, FormFixes, 2, false), 'GBG Filtered'!G8), PokemonIcons, 2, False), "") | J14: =IF('GBG Filtered'!H8 <> "", VLOOKUP(IFERROR(VLOOKUP('GBG Filtered'!H8, FormFixes, 2, false), 'GBG Filtered'!H8), PokemonIcons, 2, False), "") | K14: =IF('GBG Filtered'!I8 <> "", VLOOKUP(IFERROR(VLOOKUP('GBG Filtered'!I8, FormFixes, 2, false), 'GBG Filtered'!I8), PokemonIcons, 2, False), "") | L14: =IF('GBG Filtered'!J8 <> "", VLOOKUP(IFERROR(VLOOKUP('GBG Filtered'!J8, FormFixes, 2, false), 'GBG Filtered'!J8), PokemonIcons, 2, False), "") | P14: =IF('GBG Filtered'!N8 <> "", VLOOKUP(IFERROR(VLOOKUP('GBG Filtered'!N8, FormFixes, 2, false), 'GBG Filtered'!N8), PokemonIcons, 2, False), "") | Q14: =IF('GBG Filtered'!O8 <> "", VLOOKUP(IFERROR(VLOOKUP('GBG Filtered'!O8, FormFixes, 2, false), 'GBG Filtered'!O8), PokemonIcons, 2, False), "") | R14: =IF('GBG Filtered'!P8 <> "", VLOOKUP(IFERROR(VLOOKUP('GBG Filtered'!P8, FormFixes, 2, false), 'GBG Filtered'!P8), PokemonIcons, 2, False), "") | S14: =IF('GBG Filtered'!Q8 <> "", VLOOKUP(IFERROR(VLOOKUP('GBG Filtered'!Q8, FormFixes, 2, false), 'GBG Filtered'!Q8), PokemonIcons, 2, False), "") | U14: =IF('GBG Filtered'!S8 <> "", VLOOKUP(IFERROR(VLOOKUP('GBG Filtered'!S8, FormFixes, 2, false), 'GBG Filtered'!S8), PokemonIcons, 2, False), "") | V14: =IF('GBG Filtered'!T8 <> "", VLOOKUP(IFERROR(VLOOKUP('GBG Filtered'!T8, FormFixes, 2, false), 'GBG Filtered'!T8), PokemonIcons, 2, False), "") | W14: =IF('GBG Filtered'!U8 <> "", VLOOKUP(IFERROR(VLOOKUP('GBG Filtered'!U8, FormFixes, 2, false), 'GBG Filtered'!U8), PokemonIcons, 2, False), "") | X14: =IF('GBG Filtered'!V8 <> "", VLOOKUP(IFERROR(VLOOKUP('GBG Filtered'!V8, FormFixes, 2, false), 'GBG Filtered'!V8), PokemonIcons, 2, False), "") | AA14: =IF('GBG Filtered'!Y8 <> "", VLOOKUP(IFERROR(VLOOKUP('GBG Filtered'!Y8, FormFixes, 2, false), 'GBG Filtered'!Y8), PokemonIcons, 2, False), "") | AB14: =IF('GBG Filtered'!Z8 <> "", VLOOKUP('GBG Filtered'!Z8, TypeIcons, 2, False), "") | AC14: =IF('GBG Filtered'!AA8 <> "", VLOOKUP(IFERROR(VLOOKUP('GBG Filtered'!AA8, FormFixes, 2, false), 'GBG Filtered'!AA8), PokemonIcons, 2, False), "") | AD14: =IF('GBG Filtered'!AB8 <> "", VLOOKUP('GBG Filtered'!AB8, TypeIcons, 2, False), "") | AE14: ='GBG Filtered'!AC8 | AF14: ='GBG Filtered'!AD8 | AG14: ='GBG Filtered'!AE8
B15: ='GBG Filtered'!A9 | C15: ='GBG Filtered'!B9 | D15: ='GBG Filtered'!C9 | E15: ='GBG Filtered'!D9 | F15: =IF(B15 <> "", HYPERLINK(VLOOKUP( VALUE(B15), ReplayLinksTable, 2, false), "Replay"), "") | G15: =IF('GBG Filtered'!E9 <> "", VLOOKUP(IFERROR(VLOOKUP('GBG Filtered'!E9, FormFixes, 2, false), 'GBG Filtered'!E9), PokemonIcons, 2, False), "") | H15: =IF('GBG Filtered'!F9 <> "", VLOOKUP(IFERROR(VLOOKUP('GBG Filtered'!F9, FormFixes, 2, false), 'GBG Filtered'!F9), PokemonIcons, 2, False), "") | I15: =IF('GBG Filtered'!G9 <> "", VLOOKUP(IFERROR(VLOOKUP('GBG Filtered'!G9, FormFixes, 2, false), 'GBG Filtered'!G9), PokemonIcons, 2, False), "") | J15: =IF('GBG Filtered'!H9 <> "", VLOOKUP(IFERROR(VLOOKUP('GBG Filtered'!H9, FormFixes, 2, false), 'GBG Filtered'!H9), PokemonIcons, 2, False), "") | K15: =IF('GBG Filtered'!I9 <> "", VLOOKUP(IFERROR(VLOOKUP('GBG Filtered'!I9, FormFixes, 2, false), 'GBG Filtered'!I9), PokemonIcons, 2, False), "") | L15: =IF('GBG Filtered'!J9 <> "", VLOOKUP(IFERROR(VLOOKUP('GBG Filtered'!J9, FormFixes, 2, false), 'GBG Filtered'!J9), PokemonIcons, 2, False), "") | P15: =IF('GBG Filtered'!N9 <> "", VLOOKUP(IFERROR(VLOOKUP('GBG Filtered'!N9, FormFixes, 2, false), 'GBG Filtered'!N9), PokemonIcons, 2, False), "") | Q15: =IF('GBG Filtered'!O9 <> "", VLOOKUP(IFERROR(VLOOKUP('GBG Filtered'!O9, FormFixes, 2, false), 'GBG Filtered'!O9), PokemonIcons, 2, False), "") | R15: =IF('GBG Filtered'!P9 <> "", VLOOKUP(IFERROR(VLOOKUP('GBG Filtered'!P9, FormFixes, 2, false), 'GBG Filtered'!P9), PokemonIcons, 2, False), "") | S15: =IF('GBG Filtered'!Q9 <> "", VLOOKUP(IFERROR(VLOOKUP('GBG Filtered'!Q9, FormFixes, 2, false), 'GBG Filtered'!Q9), PokemonIcons, 2, False), "") | U15: =IF('GBG Filtered'!S9 <> "", VLOOKUP(IFERROR(VLOOKUP('GBG Filtered'!S9, FormFixes, 2, false), 'GBG Filtered'!S9), PokemonIcons, 2, False), "") | V15: =IF('GBG Filtered'!T9 <> "", VLOOKUP(IFERROR(VLOOKUP('GBG Filtered'!T9, FormFixes, 2, false), 'GBG Filtered'!T9), PokemonIcons, 2, False), "") | W15: =IF('GBG Filtered'!U9 <> "", VLOOKUP(IFERROR(VLOOKUP('GBG Filtered'!U9, FormFixes, 2, false), 'GBG Filtered'!U9), PokemonIcons, 2, False), "") | X15: =IF('GBG Filtered'!V9 <> "", VLOOKUP(IFERROR(VLOOKUP('GBG Filtered'!V9, FormFixes, 2, false), 'GBG Filtered'!V9), PokemonIcons, 2, False), "") | AA15: =IF('GBG Filtered'!Y9 <> "", VLOOKUP(IFERROR(VLOOKUP('GBG Filtered'!Y9, FormFixes, 2, false), 'GBG Filtered'!Y9), PokemonIcons, 2, False), "") | AB15: =IF('GBG Filtered'!Z9 <> "", VLOOKUP('GBG Filtered'!Z9, TypeIcons, 2, False), "") | AC15: =IF('GBG Filtered'!AA9 <> "", VLOOKUP(IFERROR(VLOOKUP('GBG Filtered'!AA9, FormFixes, 2, false), 'GBG Filtered'!AA9), PokemonIcons, 2, False), "") | AD15: =IF('GBG Filtered'!AB9 <> "", VLOOKUP('GBG Filtered'!AB9, TypeIcons, 2, False), "") | AE15: ='GBG Filtered'!AC9 | AF15: ='GBG Filtered'!AD9 | AG15: ='GBG Filtered'!AE9
B16: ='GBG Filtered'!A10 | C16: ='GBG Filtered'!B10 | D16: ='GBG Filtered'!C10 | E16: ='GBG Filtered'!D10 | F16: =IF(B16 <> "", HYPERLINK(VLOOKUP( VALUE(B16), ReplayLinksTable, 2, false), "Replay"), "") | G16: =IF('GBG Filtered'!E10 <> "", VLOOKUP(IFERROR(VLOOKUP('GBG Filtered'!E10, FormFixes, 2, false), 'GBG Filtered'!E10), PokemonIcons, 2, False), "") | H16: =IF('GBG Filtered'!F10 <> "", VLOOKUP(IFERROR(VLOOKUP('GBG Filtered'!F10, FormFixes, 2, false), 'GBG Filtered'!F10), PokemonIcons, 2, False), "") | I16: =IF('GBG Filtered'!G10 <> "", VLOOKUP(IFERROR(VLOOKUP('GBG Filtered'!G10, FormFixes, 2, false), 'GBG Filtered'!G10), PokemonIcons, 2, False), "") | J16: =IF('GBG Filtered'!H10 <> "", VLOOKUP(IFERROR(VLOOKUP('GBG Filtered'!H10, FormFixes, 2, false), 'GBG Filtered'!H10), PokemonIcons, 2, False), "") | K16: =IF('GBG Filtered'!I10 <> "", VLOOKUP(IFERROR(VLOOKUP('GBG Filtered'!I10, FormFixes, 2, false), 'GBG Filtered'!I10), PokemonIcons, 2, False), "") | L16: =IF('GBG Filtered'!J10 <> "", VLOOKUP(IFERROR(VLOOKUP('GBG Filtered'!J10, FormFixes, 2, false), 'GBG Filtered'!J10), PokemonIcons, 2, False), "") | P16: =IF('GBG Filtered'!N10 <> "", VLOOKUP(IFERROR(VLOOKUP('GBG Filtered'!N10, FormFixes, 2, false), 'GBG Filtered'!N10), PokemonIcons, 2, False), "") | Q16: =IF('GBG Filtered'!O10 <> "", VLOOKUP(IFERROR(VLOOKUP('GBG Filtered'!O10, FormFixes, 2, false), 'GBG Filtered'!O10), PokemonIcons, 2, False), "") | R16: =IF('GBG Filtered'!P10 <> "", VLOOKUP(IFERROR(VLOOKUP('GBG Filtered'!P10, FormFixes, 2, false), 'GBG Filtered'!P10), PokemonIcons, 2, False), "") | S16: =IF('GBG Filtered'!Q10 <> "", VLOOKUP(IFERROR(VLOOKUP('GBG Filtered'!Q10, FormFixes, 2, false), 'GBG Filtered'!Q10), PokemonIcons, 2, False), "") | U16: =IF('GBG Filtered'!S10 <> "", VLOOKUP(IFERROR(VLOOKUP('GBG Filtered'!S10, FormFixes, 2, false), 'GBG Filtered'!S10), PokemonIcons, 2, False), "") | V16: =IF('GBG Filtered'!T10 <> "", VLOOKUP(IFERROR(VLOOKUP('GBG Filtered'!T10, FormFixes, 2, false), 'GBG Filtered'!T10), PokemonIcons, 2, False), "") | W16: =IF('GBG Filtered'!U10 <> "", VLOOKUP(IFERROR(VLOOKUP('GBG Filtered'!U10, FormFixes, 2, false), 'GBG Filtered'!U10), PokemonIcons, 2, False), "") | X16: =IF('GBG Filtered'!V10 <> "", VLOOKUP(IFERROR(VLOOKUP('GBG Filtered'!V10, FormFixes, 2, false), 'GBG Filtered'!V10), PokemonIcons, 2, False), "") | AA16: =IF('GBG Filtered'!Y10 <> "", VLOOKUP(IFERROR(VLOOKUP('GBG Filtered'!Y10, FormFixes, 2, false), 'GBG Filtered'!Y10), PokemonIcons, 2, False), "") | AB16: =IF('GBG Filtered'!Z10 <> "", VLOOKUP('GBG Filtered'!Z10, TypeIcons, 2, False), "") | AC16: =IF('GBG Filtered'!AA10 <> "", VLOOKUP(IFERROR(VLOOKUP('GBG Filtered'!AA10, FormFixes, 2, false), 'GBG Filtered'!AA10), PokemonIcons, 2, False), "") | AD16: =IF('GBG Filtered'!AB10 <> "", VLOOKUP('GBG Filtered'!AB10, TypeIcons, 2, False), "") | AE16: ='GBG Filtered'!AC10 | AF16: ='GBG Filtered'!AD10 | AG16: ='GBG Filtered'!AE10
B17: ='GBG Filtered'!A11 | C17: ='GBG Filtered'!B11 | D17: ='GBG Filtered'!C11 | E17: ='GBG Filtered'!D11 | F17: =IF(B17 <> "", HYPERLINK(VLOOKUP( VALUE(B17), ReplayLinksTable, 2, false), "Replay"), "") | G17: =IF('GBG Filtered'!E11 <> "", VLOOKUP(IFERROR(VLOOKUP('GBG Filtered'!E11, FormFixes, 2, false), 'GBG Filtered'!E11), PokemonIcons, 2, False), "") | H17: =IF('GBG Filtered'!F11 <> "", VLOOKUP(IFERROR(VLOOKUP('GBG Filtered'!F11, FormFixes, 2, false), 'GBG Filtered'!F11), PokemonIcons, 2, False), "") | I17: =IF('GBG Filtered'!G11 <> "", VLOOKUP(IFERROR(VLOOKUP('GBG Filtered'!G11, FormFixes, 2, false), 'GBG Filtered'!G11), PokemonIcons, 2, False), "") | J17: =IF('GBG Filtered'!H11 <> "", VLOOKUP(IFERROR(VLOOKUP('GBG Filtered'!H11, FormFixes, 2, false), 'GBG Filtered'!H11), PokemonIcons, 2, False), "") | K17: =IF('GBG Filtered'!I11 <> "", VLOOKUP(IFERROR(VLOOKUP('GBG Filtered'!I11, FormFixes, 2, false), 'GBG Filtered'!I11), PokemonIcons, 2, False), "") | L17: =IF('GBG Filtered'!J11 <> "", VLOOKUP(IFERROR(VLOOKUP('GBG Filtered'!J11, FormFixes, 2, false), 'GBG Filtered'!J11), PokemonIcons, 2, False), "") | P17: =IF('GBG Filtered'!N11 <> "", VLOOKUP(IFERROR(VLOOKUP('GBG Filtered'!N11, FormFixes, 2, false), 'GBG Filtered'!N11), PokemonIcons, 2, False), "") | Q17: =IF('GBG Filtered'!O11 <> "", VLOOKUP(IFERROR(VLOOKUP('GBG Filtered'!O11, FormFixes, 2, false), 'GBG Filtered'!O11), PokemonIcons, 2, False), "") | R17: =IF('GBG Filtered'!P11 <> "", VLOOKUP(IFERROR(VLOOKUP('GBG Filtered'!P11, FormFixes, 2, false), 'GBG Filtered'!P11), PokemonIcons, 2, False), "") | S17: =IF('GBG Filtered'!Q11 <> "", VLOOKUP(IFERROR(VLOOKUP('GBG Filtered'!Q11, FormFixes, 2, false), 'GBG Filtered'!Q11), PokemonIcons, 2, False), "") | U17: =IF('GBG Filtered'!S11 <> "", VLOOKUP(IFERROR(VLOOKUP('GBG Filtered'!S11, FormFixes, 2, false), 'GBG Filtered'!S11), PokemonIcons, 2, False), "") | V17: =IF('GBG Filtered'!T11 <> "", VLOOKUP(IFERROR(VLOOKUP('GBG Filtered'!T11, FormFixes, 2, false), 'GBG Filtered'!T11), PokemonIcons, 2, False), "") | W17: =IF('GBG Filtered'!U11 <> "", VLOOKUP(IFERROR(VLOOKUP('GBG Filtered'!U11, FormFixes, 2, false), 'GBG Filtered'!U11), PokemonIcons, 2, False), "") | X17: =IF('GBG Filtered'!V11 <> "", VLOOKUP(IFERROR(VLOOKUP('GBG Filtered'!V11, FormFixes, 2, false), 'GBG Filtered'!V11), PokemonIcons, 2, False), "") | AA17: =IF('GBG Filtered'!Y11 <> "", VLOOKUP(IFERROR(VLOOKUP('GBG Filtered'!Y11, FormFixes, 2, false), 'GBG Filtered'!Y11), PokemonIcons, 2, False), "") | AB17: =IF('GBG Filtered'!Z11 <> "", VLOOKUP('GBG Filtered'!Z11, TypeIcons, 2, False), "") | AC17: =IF('GBG Filtered'!AA11 <> "", VLOOKUP(IFERROR(VLOOKUP('GBG Filtered'!AA11, FormFixes, 2, false), 'GBG Filtered'!AA11), PokemonIcons, 2, False), "") | AD17: =IF('GBG Filtered'!AB11 <> "", VLOOKUP('GBG Filtered'!AB11, TypeIcons, 2, False), "") | AE17: ='GBG Filtered'!AC11 | AF17: ='GBG Filtered'!AD11 | AG17: ='GBG Filtered'!AE11
B18: ='GBG Filtered'!A12 | C18: ='GBG Filtered'!B12 | D18: ='GBG Filtered'!C12 | E18: ='GBG Filtered'!D12 | F18: =IF(B18 <> "", HYPERLINK(VLOOKUP( VALUE(B18), ReplayLinksTable, 2, false), "Replay"), "") | G18: =IF('GBG Filtered'!E12 <> "", VLOOKUP(IFERROR(VLOOKUP('GBG Filtered'!E12, FormFixes, 2, false), 'GBG Filtered'!E12), PokemonIcons, 2, False), "") | H18: =IF('GBG Filtered'!F12 <> "", VLOOKUP(IFERROR(VLOOKUP('GBG Filtered'!F12, FormFixes, 2, false), 'GBG Filtered'!F12), PokemonIcons, 2, False), "") | I18: =IF('GBG Filtered'!G12 <> "", VLOOKUP(IFERROR(VLOOKUP('GBG Filtered'!G12, FormFixes, 2, false), 'GBG Filtered'!G12), PokemonIcons, 2, False), "") | J18: =IF('GBG Filtered'!H12 <> "", VLOOKUP(IFERROR(VLOOKUP('GBG Filtered'!H12, FormFixes, 2, false), 'GBG Filtered'!H12), PokemonIcons, 2, False), "") | K18: =IF('GBG Filtered'!I12 <> "", VLOOKUP(IFERROR(VLOOKUP('GBG Filtered'!I12, FormFixes, 2, false), 'GBG Filtered'!I12), PokemonIcons, 2, False), "") | L18: =IF('GBG Filtered'!J12 <> "", VLOOKUP(IFERROR(VLOOKUP('GBG Filtered'!J12, FormFixes, 2, false), 'GBG Filtered'!J12), PokemonIcons, 2, False), "") | P18: =IF('GBG Filtered'!N12 <> "", VLOOKUP(IFERROR(VLOOKUP('GBG Filtered'!N12, FormFixes, 2, false), 'GBG Filtered'!N12), PokemonIcons, 2, False), "") | Q18: =IF('GBG Filtered'!O12 <> "", VLOOKUP(IFERROR(VLOOKUP('GBG Filtered'!O12, FormFixes, 2, false), 'GBG Filtered'!O12), PokemonIcons, 2, False), "") | R18: =IF('GBG Filtered'!P12 <> "", VLOOKUP(IFERROR(VLOOKUP('GBG Filtered'!P12, FormFixes, 2, false), 'GBG Filtered'!P12), PokemonIcons, 2, False), "") | S18: =IF('GBG Filtered'!Q12 <> "", VLOOKUP(IFERROR(VLOOKUP('GBG Filtered'!Q12, FormFixes, 2, false), 'GBG Filtered'!Q12), PokemonIcons, 2, False), "") | U18: =IF('GBG Filtered'!S12 <> "", VLOOKUP(IFERROR(VLOOKUP('GBG Filtered'!S12, FormFixes, 2, false), 'GBG Filtered'!S12), PokemonIcons, 2, False), "") | V18: =IF('GBG Filtered'!T12 <> "", VLOOKUP(IFERROR(VLOOKUP('GBG Filtered'!T12, FormFixes, 2, false), 'GBG Filtered'!T12), PokemonIcons, 2, False), "") | W18: =IF('GBG Filtered'!U12 <> "", VLOOKUP(IFERROR(VLOOKUP('GBG Filtered'!U12, FormFixes, 2, false), 'GBG Filtered'!U12), PokemonIcons, 2, False), "") | X18: =IF('GBG Filtered'!V12 <> "", VLOOKUP(IFERROR(VLOOKUP('GBG Filtered'!V12, FormFixes, 2, false), 'GBG Filtered'!V12), PokemonIcons, 2, False), "") | AA18: =IF('GBG Filtered'!Y12 <> "", VLOOKUP(IFERROR(VLOOKUP('GBG Filtered'!Y12, FormFixes, 2, false), 'GBG Filtered'!Y12), PokemonIcons, 2, False), "") | AB18: =IF('GBG Filtered'!Z12 <> "", VLOOKUP('GBG Filtered'!Z12, TypeIcons, 2, False), "") | AC18: =IF('GBG Filtered'!AA12 <> "", VLOOKUP(IFERROR(VLOOKUP('GBG Filtered'!AA12, FormFixes, 2, false), 'GBG Filtered'!AA12), PokemonIcons, 2, False), "") | AD18: =IF('GBG Filtered'!AB12 <> "", VLOOKUP('GBG Filtered'!AB12, TypeIcons, 2, False), "") | AE18: ='GBG Filtered'!AC12 | AF18: ='GBG Filtered'!AD12 | AG18: ='GBG Filtered'!AE12
B19: ='GBG Filtered'!A13 | C19: ='GBG Filtered'!B13 | D19: ='GBG Filtered'!C13 | E19: ='GBG Filtered'!D13 | F19: =IF(B19 <> "", HYPERLINK(VLOOKUP( VALUE(B19), ReplayLinksTable, 2, false), "Replay"), "") | G19: =IF('GBG Filtered'!E13 <> "", VLOOKUP(IFERROR(VLOOKUP('GBG Filtered'!E13, FormFixes, 2, false), 'GBG Filtered'!E13), PokemonIcons, 2, False), "") | H19: =IF('GBG Filtered'!F13 <> "", VLOOKUP(IFERROR(VLOOKUP('GBG Filtered'!F13, FormFixes, 2, false), 'GBG Filtered'!F13), PokemonIcons, 2, False), "") | I19: =IF('GBG Filtered'!G13 <> "", VLOOKUP(IFERROR(VLOOKUP('GBG Filtered'!G13, FormFixes, 2, false), 'GBG Filtered'!G13), PokemonIcons, 2, False), "") | J19: =IF('GBG Filtered'!H13 <> "", VLOOKUP(IFERROR(VLOOKUP('GBG Filtered'!H13, FormFixes, 2, false), 'GBG Filtered'!H13), PokemonIcons, 2, False), "") | K19: =IF('GBG Filtered'!I13 <> "", VLOOKUP(IFERROR(VLOOKUP('GBG Filtered'!I13, FormFixes, 2, false), 'GBG Filtered'!I13), PokemonIcons, 2, False), "") | L19: =IF('GBG Filtered'!J13 <> "", VLOOKUP(IFERROR(VLOOKUP('GBG Filtered'!J13, FormFixes, 2, false), 'GBG Filtered'!J13), PokemonIcons, 2, False), "") | P19: =IF('GBG Filtered'!N13 <> "", VLOOKUP(IFERROR(VLOOKUP('GBG Filtered'!N13, FormFixes, 2, false), 'GBG Filtered'!N13), PokemonIcons, 2, False), "") | Q19: =IF('GBG Filtered'!O13 <> "", VLOOKUP(IFERROR(VLOOKUP('GBG Filtered'!O13, FormFixes, 2, false), 'GBG Filtered'!O13), PokemonIcons, 2, False), "") | R19: =IF('GBG Filtered'!P13 <> "", VLOOKUP(IFERROR(VLOOKUP('GBG Filtered'!P13, FormFixes, 2, false), 'GBG Filtered'!P13), PokemonIcons, 2, False), "") | S19: =IF('GBG Filtered'!Q13 <> "", VLOOKUP(IFERROR(VLOOKUP('GBG Filtered'!Q13, FormFixes, 2, false), 'GBG Filtered'!Q13), PokemonIcons, 2, False), "") | U19: =IF('GBG Filtered'!S13 <> "", VLOOKUP(IFERROR(VLOOKUP('GBG Filtered'!S13, FormFixes, 2, false), 'GBG Filtered'!S13), PokemonIcons, 2, False), "") | V19: =IF('GBG Filtered'!T13 <> "", VLOOKUP(IFERROR(VLOOKUP('GBG Filtered'!T13, FormFixes, 2, false), 'GBG Filtered'!T13), PokemonIcons, 2, False), "") | W19: =IF('GBG Filtered'!U13 <> "", VLOOKUP(IFERROR(VLOOKUP('GBG Filtered'!U13, FormFixes, 2, false), 'GBG Filtered'!U13), PokemonIcons, 2, False), "") | X19: =IF('GBG Filtered'!V13 <> "", VLOOKUP(IFERROR(VLOOKUP('GBG Filtered'!V13, FormFixes, 2, false), 'GBG Filtered'!V13), PokemonIcons, 2, False), "") | AA19: =IF('GBG Filtered'!Y13 <> "", VLOOKUP(IFERROR(VLOOKUP('GBG Filtered'!Y13, FormFixes, 2, false), 'GBG Filtered'!Y13), PokemonIcons, 2, False), "") | AB19: =IF('GBG Filtered'!Z13 <> "", VLOOKUP('GBG Filtered'!Z13, TypeIcons, 2, False), "") | AC19: =IF('GBG Filtered'!AA13 <> "", VLOOKUP(IFERROR(VLOOKUP('GBG Filtered'!AA13, FormFixes, 2, false), 'GBG Filtered'!AA13), PokemonIcons, 2, False), "") | AD19: =IF('GBG Filtered'!AB13 <> "", VLOOKUP('GBG Filtered'!AB13, TypeIcons, 2, False), "") | AE19: ='GBG Filtered'!AC13 | AF19: ='GBG Filtered'!AD13 | AG19: ='GBG Filtered'!AE13
... B507: ='GBG Filtered'!A501 | C507: ='GBG Filtered'!B501 | D507: ='GBG Filtered'!C501 | E507: ='GBG Filtered'!D501 | F507: =IF(B507 <> "", HYPERLINK(VLOOKUP( VALUE(B507), ReplayLinksTable, 2, false), "Replay"), "") | G507: =IF('GBG Filtered'!E501 <> "", VLOOKUP(IFERROR(VLOOKUP('GBG Filtered'!E501, FormFixes, 2, false), 'GBG Filtered'!E501), PokemonIcons, 2, False), "") | H507: =IF('GBG Filtered'!F501 <> "", VLOOKUP(IFERROR(VLOOKUP('GBG Filtered'!F501, FormFixes, 2, false), 'GBG Filtered'!F501), PokemonIcons, 2, False), "") | I507: =IF('GBG Filtered'!G501 <> "", VLOOKUP(IFERROR(VLOOKUP('GBG Filtered'!G501, FormFixes, 2, false), 'GBG Filtered'!G501), PokemonIcons, 2, False), "") | J507: =IF('GBG Filtered'!H501 <> "", VLOOKUP(IFERROR(VLOOKUP('GBG Filtered'!H501, FormFixes, 2, false), 'GBG Filtered'!H501), PokemonIcons, 2, False), "") | K507: =IF('GBG Filtered'!I501 <> "", VLOOKUP(IFERROR(VLOOKUP('GBG Filtered'!I501, FormFixes, 2, false), 'GBG Filtered'!I501), PokemonIcons, 2, False), "") | L507: =IF('GBG Filtered'!J501 <> "", VLOOKUP(IFERROR(VLOOKUP('GBG Filtered'!J501, FormFixes, 2, false), 'GBG Filtered'!J501), PokemonIcons, 2, False), "") | P507: =IF('GBG Filtered'!N501 <> "", VLOOKUP(IFERROR(VLOOKUP('GBG Filtered'!N501, FormFixes, 2, false), 'GBG Filtered'!N501), PokemonIcons, 2, False), "") | Q507: =IF('GBG Filtered'!O501 <> "", VLOOKUP(IFERROR(VLOOKUP('GBG Filtered'!O501, FormFixes, 2, false), 'GBG Filtered'!O501), PokemonIcons, 2, False), "") | R507: =IF('GBG Filtered'!P501 <> "", VLOOKUP(IFERROR(VLOOKUP('GBG Filtered'!P501, FormFixes, 2, false), 'GBG Filtered'!P501), PokemonIcons, 2, False), "") | S507: =IF('GBG Filtered'!Q501 <> "", VLOOKUP(IFERROR(VLOOKUP('GBG Filtered'!Q501, FormFixes, 2, false), 'GBG Filtered'!Q501), PokemonIcons, 2, False), "") | U507: =IF('GBG Filtered'!S501 <> "", VLOOKUP(IFERROR(VLOOKUP('GBG Filtered'!S501, FormFixes, 2, false), 'GBG Filtered'!S501), PokemonIcons, 2, False), "") | V507: =IF('GBG Filtered'!T501 <> "", VLOOKUP(IFERROR(VLOOKUP('GBG Filtered'!T501, FormFixes, 2, false), 'GBG Filtered'!T501), PokemonIcons, 2, False), "") | W507: =IF('GBG Filtered'!U501 <> "", VLOOKUP(IFERROR(VLOOKUP('GBG Filtered'!U501, FormFixes, 2, false), 'GBG Filtered'!U501), PokemonIcons, 2, False), "") | X507: =IF('GBG Filtered'!V501 <> "", VLOOKUP(IFERROR(VLOOKUP('GBG Filtered'!V501, FormFixes, 2, false), 'GBG Filtered'!V501), PokemonIcons, 2, False), "") | AA507: =IF('GBG Filtered'!Y501 <> "", VLOOKUP(IFERROR(VLOOKUP('GBG Filtered'!Y501, FormFixes, 2, false), 'GBG Filtered'!Y501), PokemonIcons, 2, False), "") | AB507: =IF('GBG Filtered'!Z501 <> "", VLOOKUP('GBG Filtered'!Z501, TypeIcons, 2, False), "") | AC507: =IF('GBG Filtered'!AA501 <> "", VLOOKUP(IFERROR(VLOOKUP('GBG Filtered'!AA501, FormFixes, 2, false), 'GBG Filtered'!AA501), PokemonIcons, 2, False), "") | AD507: =IF('GBG Filtered'!AB501 <> "", VLOOKUP('GBG Filtered'!AB501, TypeIcons, 2, False), "") | AE507: ='GBG Filtered'!AC501 | AF507: ='GBG Filtered'!AD501 | AG507: ='GBG Filtered'!AE501

Sheet Match by Match
B2: Set | E2: Opposing Team | O2: Replay Links | T2: Match Notes
B3: =IF('MBM Data'!J2 <> "", 'MBM Data'!A2, "") | C3: ='MBM Data'!J2 | D3: =IF(E3 <> "", "vs", "") | E3: ='MBM Data'!B2 | F3: =IF('MBM Data'!C2 <> "", VLOOKUP(IFERROR(VLOOKUP('MBM Data'!C2, FormFixes, 2, false), 'MBM Data'!C2), PokemonIcons, 2, False), "") | G3: =IF('MBM Data'!D2 <> "", VLOOKUP(IFERROR(VLOOKUP('MBM Data'!D2, FormFixes, 2, false), 'MBM Data'!D2), PokemonIcons, 2, False), "") | H3: =IF('MBM Data'!E2 <> "", VLOOKUP(IFERROR(VLOOKUP('MBM Data'!E2, FormFixes, 2, false), 'MBM Data'!E2), PokemonIcons, 2, False), "") | I3: =IF('MBM Data'!F2 <> "", VLOOKUP(IFERROR(VLOOKUP('MBM Data'!F2, FormFixes, 2, false), 'MBM Data'!F2), PokemonIcons, 2, False), "") | J3: =IF('MBM Data'!G2 <> "", VLOOKUP(IFERROR(VLOOKUP('MBM Data'!G2, FormFixes, 2, false), 'MBM Data'!G2), PokemonIcons, 2, False), "") | K3: =IF('MBM Data'!H2 <> "", VLOOKUP(IFERROR(VLOOKUP('MBM Data'!H2, FormFixes, 2, false), 'MBM Data'!H2), PokemonIcons, 2, False), "") | O3: =IFERROR(IF('MBM Data'!K2 <> "n/a", HYPERLINK('MBM Data'!K2, "G1"), ""), "") | P3: =IFERROR(IF('MBM Data'!L2 <> "n/a", HYPERLINK('MBM Data'!L2, "G2"), ""), "") | Q3: =IFERROR(IF('MBM Data'!M2 <> "n/a", HYPERLINK('MBM Data'!M2, "G3"), ""), "")
B4: =IF('MBM Data'!J3 <> "", 'MBM Data'!A3, "") | C4: ='MBM Data'!J3 | D4: =IF(E4 <> "", "vs", "") | E4: ='MBM Data'!B3 | F4: =IF('MBM Data'!C3 <> "", VLOOKUP(IFERROR(VLOOKUP('MBM Data'!C3, FormFixes, 2, false), 'MBM Data'!C3), PokemonIcons, 2, False), "") | G4: =IF('MBM Data'!D3 <> "", VLOOKUP(IFERROR(VLOOKUP('MBM Data'!D3, FormFixes, 2, false), 'MBM Data'!D3), PokemonIcons, 2, False), "") | H4: =IF('MBM Data'!E3 <> "", VLOOKUP(IFERROR(VLOOKUP('MBM Data'!E3, FormFixes, 2, false), 'MBM Data'!E3), PokemonIcons, 2, False), "") | I4: =IF('MBM Data'!F3 <> "", VLOOKUP(IFERROR(VLOOKUP('MBM Data'!F3, FormFixes, 2, false), 'MBM Data'!F3), PokemonIcons, 2, False), "") | J4: =IF('MBM Data'!G3 <> "", VLOOKUP(IFERROR(VLOOKUP('MBM Data'!G3, FormFixes, 2, false), 'MBM Data'!G3), PokemonIcons, 2, False), "") | K4: =IF('MBM Data'!H3 <> "", VLOOKUP(IFERROR(VLOOKUP('MBM Data'!H3, FormFixes, 2, false), 'MBM Data'!H3), PokemonIcons, 2, False), "") | O4: =IFERROR(IF('MBM Data'!K3 <> "n/a", HYPERLINK('MBM Data'!K3, "G1"), ""), "") | P4: =IFERROR(IF('MBM Data'!L3 <> "n/a", HYPERLINK('MBM Data'!L3, "G2"), ""), "") | Q4: =IFERROR(IF('MBM Data'!M3 <> "n/a", HYPERLINK('MBM Data'!M3, "G3"), ""), "")
